<?xml version="1.0"?>
<sdf version="1.9">
  <model name="omni_like_robot" canonical_link="chassis">
    <pose>0 0 0 0 0 0</pose>

    <!-- CHASSIS -->
    <link name="chassis">
      <pose>0 0 0.05 0 0 0</pose>
      <inertial>
        <mass>1.0</mass>
        <inertia>
          <ixx>0.07315</ixx>
          <iyy>0.151641</iyy>
          <izz>0.219727</izz>
          <ixy>-0.0</ixy>
          <iyz>0.0</iyz>
          <ixz>-2.7e-05</ixz>
        </inertia>
      </inertial>
      <visual name="chassis_visual">
        <geometry>
          <mesh>
            <uri>meshes/base_link.stl</uri>
            <scale>0.001 0.001 0.001</scale>
          </mesh>
        </geometry>
        <material>
          <ambient>0.0 0.612 0.867 1</ambient>
          <diffuse>0.0 0.612 0.867 1</diffuse>
        </material>
      </visual>
      <collision name="chassis_collision">
        <geometry>
          <mesh>
            <uri>meshes/base_link.stl</uri>
            <scale>0.001 0.001 0.001</scale>
          </mesh>
        </geometry>
      </collision>
    </link>

    <!-- WHEELS -->

    <!-- FRONT LEFT -->
<link name="front_left_wheel">

  <!-- Position taken from old working chassis -->
  <pose>0 0 0.05 0 0 0</pose>

  <!-- Inertial from URDF -->
  <inertial>
    <!-- <pose>-2.1897287448918723e-05 -0.023738528231967565 3.1378817485983033e-06 0 0 0</pose> -->
    <mass>0.30282113324994747</mass>
    <inertia>
      <ixx>0.00016</ixx>
      <iyy>0.000181</iyy>
      <izz>0.000158</izz>
      <ixy>-1e-06</ixy>
      <iyz>0.0</iyz>
      <ixz>-0.0</ixz>
    </inertia>
  </inertial>

  <!-- Visual -->
  <visual name="visual">
    <!-- <pose>-0.125 -0.15 0 0 0 0</pose> -->
    <geometry>
      <mesh>
        <uri>meshes/wheel_frame_FL_1.stl</uri>
        <scale>0.001 0.001 0.001</scale>
      </mesh>
    </geometry>
    <material>
      <ambient>0.75 0.75 0.75 1</ambient>
      <diffuse>0.85 0.85 0.85 1</diffuse>
      <specular>0.9 0.9 0.9 1</specular>
    </material>
  </visual>

  <!-- Collision -->
  <collision name="collision">
    <!-- <pose>-0.125 -0.15 0 0 0 0</pose> -->
    <geometry>
      <mesh>
        <uri>meshes/wheel_frame_FL_1.stl</uri>
        <scale>0.001 0.001 0.001</scale>
      </mesh>
    </geometry>

    <!-- Friction model copied from working mecanum -->

    <surface>
      <friction>
        <ode>
          <mu>0.2</mu>
          <mu2>0.2</mu2>
        </ode>
      </friction>
    </surface>

  </collision>

</link>

<link name="roller_14_1">

  <!-- Keep all rollers consistent with wheel reference frame -->
  <pose>0 0 0.05 0 0 0</pose>

  <!-- Inertial (from URDF) -->
  <inertial>
    <mass>0.014233736590697255</mass>
    <inertia>
      <ixx>2e-06</ixx>
      <iyy>2e-06</iyy>
      <izz>2e-06</izz>
      <ixy>-1e-06</ixy>
      <iyz>-0.0</iyz>
      <ixz>-0.0</ixz>
    </inertia>
  </inertial>

  <!-- Visual -->
  <visual name="visual">
    <geometry>
      <mesh>
        <uri>meshes/roller_14_1.stl</uri>
        <scale>0.001 0.001 0.001</scale>
      </mesh>
    </geometry>

    <!-- Same silver as wheels -->
    <material>
      <ambient>0.75 0.75 0.75 1</ambient>
      <diffuse>0.85 0.85 0.85 1</diffuse>
      <specular>0.9 0.9 0.9 1</specular>
    </material>
  </visual>

  <!-- Collision -->
  <collision name="collision">
    <geometry>
      <mesh>
        <uri>meshes/roller_14_1.stl</uri>
        <scale>0.001 0.001 0.001</scale>
      </mesh>
    </geometry>

    <!-- Same friction model -->
    <surface>
      <friction>
        <ode>
          <mu>0.2</mu>
          <mu2>0.2</mu2>
        </ode>
      </friction>
    </surface>
  </collision>

</link>

<link name="roller_16_1">

  <!-- Keep all rollers consistent with wheel reference frame -->
  <pose>0 0 0.05 0 0 0</pose>

  <!-- Inertial (from URDF) -->
  <inertial>
    <mass>0.014233736590697255</mass>
    <inertia>
      <ixx>2e-06</ixx>
      <iyy>2e-06</iyy>
      <izz>2e-06</izz>
      <ixy>-1e-06</ixy>
      <iyz>-0.0</iyz>
      <ixz>-0.0</ixz>
    </inertia>
  </inertial>

  <!-- Visual -->
  <visual name="visual">
    <geometry>
      <mesh>
        <uri>meshes/roller_16_1.stl</uri>
        <scale>0.001 0.001 0.001</scale>
      </mesh>
    </geometry>

    <!-- Same silver as wheels -->
    <material>
      <ambient>0.75 0.75 0.75 1</ambient>
      <diffuse>0.85 0.85 0.85 1</diffuse>
      <specular>0.9 0.9 0.9 1</specular>
    </material>
  </visual>

  <!-- Collision -->
  <collision name="collision">
    <geometry>
      <mesh>
        <uri>meshes/roller_16_1.stl</uri>
        <scale>0.001 0.001 0.001</scale>
      </mesh>
    </geometry>

    <!-- Same friction model -->
    <surface>
      <friction>
        <ode>
          <mu>0.2</mu>
          <mu2>0.2</mu2>
        </ode>
      </friction>
    </surface>
  </collision>

</link>

<link name="roller_13_1">

  <!-- Keep all rollers consistent with wheel reference frame -->
  <pose>0 0 0.05 0 0 0</pose>

  <!-- Inertial (from URDF) -->
  <inertial>
    <mass>0.014233736590697255</mass>
    <inertia>
      <ixx>2e-06</ixx>
      <iyy>2e-06</iyy>
      <izz>2e-06</izz>
      <ixy>-1e-06</ixy>
      <iyz>-0.0</iyz>
      <ixz>-0.0</ixz>
    </inertia>
  </inertial>

  <!-- Visual -->
  <visual name="visual">
    <geometry>
      <mesh>
        <uri>meshes/roller_13_1.stl</uri>
        <scale>0.001 0.001 0.001</scale>
      </mesh>
    </geometry>

    <!-- Same silver as wheels -->
    <material>
      <ambient>0.75 0.75 0.75 1</ambient>
      <diffuse>0.85 0.85 0.85 1</diffuse>
      <specular>0.9 0.9 0.9 1</specular>
    </material>
  </visual>

  <!-- Collision -->
  <collision name="collision">
    <geometry>
      <mesh>
        <uri>meshes/roller_13_1.stl</uri>
        <scale>0.001 0.001 0.001</scale>
      </mesh>
    </geometry>

    <!-- Same friction model -->
    <surface>
      <friction>
        <ode>
          <mu>0.2</mu>
          <mu2>0.2</mu2>
        </ode>
      </friction>
    </surface>
  </collision>

</link>


<link name="roller_12_1">

  <!-- Keep all rollers consistent with wheel reference frame -->
  <pose>0 0 0.05 0 0 0</pose>

  <!-- Inertial (from URDF) -->
  <inertial>
    <mass>0.014233736590697255</mass>
    <inertia>
      <ixx>2e-06</ixx>
      <iyy>2e-06</iyy>
      <izz>2e-06</izz>
      <ixy>-1e-06</ixy>
      <iyz>-0.0</iyz>
      <ixz>-0.0</ixz>
    </inertia>
  </inertial>

  <!-- Visual -->
  <visual name="visual">
    <geometry>
      <mesh>
        <uri>meshes/roller_12_1.stl</uri>
        <scale>0.001 0.001 0.001</scale>
      </mesh>
    </geometry>

    <!-- Same silver as wheels -->
    <material>
      <ambient>0.75 0.75 0.75 1</ambient>
      <diffuse>0.85 0.85 0.85 1</diffuse>
      <specular>0.9 0.9 0.9 1</specular>
    </material>
  </visual>

  <!-- Collision -->
  <collision name="collision">
    <geometry>
      <mesh>
        <uri>meshes/roller_12_1.stl</uri>
        <scale>0.001 0.001 0.001</scale>
      </mesh>
    </geometry>

    <!-- Same friction model -->
    <surface>
      <friction>
        <ode>
          <mu>0.2</mu>
          <mu2>0.2</mu2>
        </ode>
      </friction>
    </surface>
  </collision>

</link>


<link name="roller_15_1">

  <!-- Keep all rollers consistent with wheel reference frame -->
  <pose>0 0 0.05 0 0 0</pose>

  <!-- Inertial (from URDF) -->
  <inertial>
    <mass>0.014233736590697255</mass>
    <inertia>
      <ixx>2e-06</ixx>
      <iyy>2e-06</iyy>
      <izz>2e-06</izz>
      <ixy>-1e-06</ixy>
      <iyz>-0.0</iyz>
      <ixz>-0.0</ixz>
    </inertia>
  </inertial>

  <!-- Visual -->
  <visual name="visual">
    <geometry>
      <mesh>
        <uri>meshes/roller_15_1.stl</uri>
        <scale>0.001 0.001 0.001</scale>
      </mesh>
    </geometry>

    <!-- Same silver as wheels -->
    <material>
      <ambient>0.75 0.75 0.75 1</ambient>
      <diffuse>0.85 0.85 0.85 1</diffuse>
      <specular>0.9 0.9 0.9 1</specular>
    </material>
  </visual>

  <!-- Collision -->
  <collision name="collision">
    <geometry>
      <mesh>
        <uri>meshes/roller_15_1.stl</uri>
        <scale>0.001 0.001 0.001</scale>
      </mesh>
    </geometry>

    <!-- Same friction model -->
    <surface>
      <friction>
        <ode>
          <mu>0.2</mu>
          <mu2>0.2</mu2>
        </ode>
      </friction>
    </surface>
  </collision>

</link>


<link name="roller_17_1">

  <!-- Keep all rollers consistent with wheel reference frame -->
  <pose>0 0 0.05 0 0 0</pose>

  <!-- Inertial (from URDF) -->
  <inertial>
    <mass>0.014233736590697255</mass>
    <inertia>
      <ixx>2e-06</ixx>
      <iyy>2e-06</iyy>
      <izz>2e-06</izz>
      <ixy>-1e-06</ixy>
      <iyz>-0.0</iyz>
      <ixz>-0.0</ixz>
    </inertia>
  </inertial>

  <!-- Visual -->
  <visual name="visual">
    <geometry>
      <mesh>
        <uri>meshes/roller_17_1.stl</uri>
        <scale>0.001 0.001 0.001</scale>
      </mesh>
    </geometry>

    <!-- Same silver as wheels -->
    <material>
      <ambient>0.75 0.75 0.75 1</ambient>
      <diffuse>0.85 0.85 0.85 1</diffuse>
      <specular>0.9 0.9 0.9 1</specular>
    </material>
  </visual>

  <!-- Collision -->
  <collision name="collision">
    <geometry>
      <mesh>
        <uri>meshes/roller_17_1.stl</uri>
        <scale>0.001 0.001 0.001</scale>
      </mesh>
    </geometry>

    <!-- Same friction model -->
    <surface>
      <friction>
        <ode>
          <mu>0.2</mu>
          <mu2>0.2</mu2>
        </ode>
      </friction>
    </surface>
  </collision>

</link>


<link name="roller_18_1">

  <!-- Keep all rollers consistent with wheel reference frame -->
  <pose>0 0 0.05 0 0 0</pose>

  <!-- Inertial (from URDF) -->
  <inertial>
    <mass>0.014233736590697255</mass>
    <inertia>
      <ixx>2e-06</ixx>
      <iyy>2e-06</iyy>
      <izz>2e-06</izz>
      <ixy>-1e-06</ixy>
      <iyz>-0.0</iyz>
      <ixz>-0.0</ixz>
    </inertia>
  </inertial>

  <!-- Visual -->
  <visual name="visual">
    <geometry>
      <mesh>
        <uri>meshes/roller_18_1.stl</uri>
        <scale>0.001 0.001 0.001</scale>
      </mesh>
    </geometry>

    <!-- Same silver as wheels -->
    <material>
      <ambient>0.75 0.75 0.75 1</ambient>
      <diffuse>0.85 0.85 0.85 1</diffuse>
      <specular>0.9 0.9 0.9 1</specular>
    </material>
  </visual>

  <!-- Collision -->
  <collision name="collision">
    <geometry>
      <mesh>
        <uri>meshes/roller_18_1.stl</uri>
        <scale>0.001 0.001 0.001</scale>
      </mesh>
    </geometry>

    <!-- Same friction model -->
    <surface>
      <friction>
        <ode>
          <mu>0.2</mu>
          <mu2>0.2</mu2>
        </ode>
      </friction>
    </surface>
  </collision>

</link>


<link name="roller_10_1">

  <!-- Keep all rollers consistent with wheel reference frame -->
  <pose>0 0 0.05 0 0 0</pose>

  <!-- Inertial (from URDF) -->
  <inertial>
    <mass>0.014233736590697255</mass>
    <inertia>
      <ixx>2e-06</ixx>
      <iyy>2e-06</iyy>
      <izz>2e-06</izz>
      <ixy>-1e-06</ixy>
      <iyz>-0.0</iyz>
      <ixz>-0.0</ixz>
    </inertia>
  </inertial>

  <!-- Visual -->
  <visual name="visual">
    <geometry>
      <mesh>
        <uri>meshes/roller_10_1.stl</uri>
        <scale>0.001 0.001 0.001</scale>
      </mesh>
    </geometry>

    <!-- Same silver as wheels -->
    <material>
      <ambient>0.75 0.75 0.75 1</ambient>
      <diffuse>0.85 0.85 0.85 1</diffuse>
      <specular>0.9 0.9 0.9 1</specular>
    </material>
  </visual>

  <!-- Collision -->
  <collision name="collision">
    <geometry>
      <mesh>
        <uri>meshes/roller_10_1.stl</uri>
        <scale>0.001 0.001 0.001</scale>
      </mesh>
    </geometry>

    <!-- Same friction model -->
    <surface>
      <friction>
        <ode>
          <mu>0.2</mu>
          <mu2>0.2</mu2>
        </ode>
      </friction>
    </surface>
  </collision>

</link>


<link name="roller_11_1">

  <!-- Keep all rollers consistent with wheel reference frame -->
  <pose>0 0 0.05 0 0 0</pose>

  <!-- Inertial (from URDF) -->
  <inertial>
    <mass>0.014233736590697255</mass>
    <inertia>
      <ixx>2e-06</ixx>
      <iyy>2e-06</iyy>
      <izz>2e-06</izz>
      <ixy>-1e-06</ixy>
      <iyz>-0.0</iyz>
      <ixz>-0.0</ixz>
    </inertia>
  </inertial>

  <!-- Visual -->
  <visual name="visual">
    <geometry>
      <mesh>
        <uri>meshes/roller_11_1.stl</uri>
        <scale>0.001 0.001 0.001</scale>
      </mesh>
    </geometry>

    <!-- Same silver as wheels -->
    <material>
      <ambient>0.75 0.75 0.75 1</ambient>
      <diffuse>0.85 0.85 0.85 1</diffuse>
      <specular>0.9 0.9 0.9 1</specular>
    </material>
  </visual>

  <!-- Collision -->
  <collision name="collision">
    <geometry>
      <mesh>
        <uri>meshes/roller_11_1.stl</uri>
        <scale>0.001 0.001 0.001</scale>
      </mesh>
    </geometry>

    <!-- Same friction model -->
    <surface>
      <friction>
        <ode>
          <mu>0.2</mu>
          <mu2>0.2</mu2>
        </ode>
      </friction>
    </surface>
  </collision>

</link>




    <!-- FRONT RIGHT -->
<link name="front_right_wheel">

  <!-- Same reference height as your final wheel -->
  <pose>0 0 0.05 0 0 0</pose>

  <!-- Inertial (from URDF, unchanged) -->
  <inertial>
    <mass>0.30282113324994747</mass>
    <inertia>
      <ixx>0.00016</ixx>
      <iyy>0.000181</iyy>
      <izz>0.000158</izz>
      <ixy>-1e-06</ixy>
      <iyz>0.0</iyz>
      <ixz>-0.0</ixz>
    </inertia>
  </inertial>

  <!-- Visual -->
  <visual name="visual">
    <geometry>
      <mesh>
        <uri>meshes/wheel_frame_FR_1.stl</uri>
        <scale>0.001 0.001 0.001</scale>
      </mesh>
    </geometry>
    <material>
      <ambient>0.75 0.75 0.75 1</ambient>
      <diffuse>0.85 0.85 0.85 1</diffuse>
      <specular>0.9 0.9 0.9 1</specular>
    </material>
  </visual>

  <!-- Collision -->
  <collision name="collision">
    <geometry>
      <mesh>
        <uri>meshes/wheel_frame_FR_1.stl</uri>
        <scale>0.001 0.001 0.001</scale>
      </mesh>
    </geometry>

    <!-- Same friction as your final definition -->
    <surface>
      <friction>
        <ode>
          <mu>0.2</mu>
          <mu2>0.2</mu2>
        </ode>
      </friction>
    </surface>

  </collision>

</link>

<link name="roller_7_1">

  <!-- Keep all rollers consistent with wheel reference frame -->
  <pose>0 0 0.05 0 0 0</pose>

  <!-- Inertial (from URDF) -->
  <inertial>
    <mass>0.014233736590697255</mass>
    <inertia>
      <ixx>2e-06</ixx>
      <iyy>2e-06</iyy>
      <izz>2e-06</izz>
      <ixy>-1e-06</ixy>
      <iyz>-0.0</iyz>
      <ixz>-0.0</ixz>
    </inertia>
  </inertial>

  <!-- Visual -->
  <visual name="visual">
    <geometry>
      <mesh>
        <uri>meshes/roller_7_1.stl</uri>
        <scale>0.001 0.001 0.001</scale>
      </mesh>
    </geometry>

    <!-- Same silver as wheels -->
    <material>
      <ambient>0.75 0.75 0.75 1</ambient>
      <diffuse>0.85 0.85 0.85 1</diffuse>
      <specular>0.9 0.9 0.9 1</specular>
    </material>
  </visual>

  <!-- Collision -->
  <collision name="collision">
    <geometry>
      <mesh>
        <uri>meshes/roller_7_1.stl</uri>
        <scale>0.001 0.001 0.001</scale>
      </mesh>
    </geometry>

    <!-- Same friction model -->
    <surface>
      <friction>
        <ode>
          <mu>0.2</mu>
          <mu2>0.2</mu2>
        </ode>
      </friction>
    </surface>
  </collision>

</link>

<link name="roller_5_1">

  <!-- Keep all rollers consistent with wheel reference frame -->
  <pose>0 0 0.05 0 0 0</pose>

  <!-- Inertial (from URDF) -->
  <inertial>
    <mass>0.014233736590697255</mass>
    <inertia>
      <ixx>2e-06</ixx>
      <iyy>2e-06</iyy>
      <izz>2e-06</izz>
      <ixy>-1e-06</ixy>
      <iyz>-0.0</iyz>
      <ixz>-0.0</ixz>
    </inertia>
  </inertial>

  <!-- Visual -->
  <visual name="visual">
    <geometry>
      <mesh>
        <uri>meshes/roller_5_1.stl</uri>
        <scale>0.001 0.001 0.001</scale>
      </mesh>
    </geometry>

    <!-- Same silver as wheels -->
    <material>
      <ambient>0.75 0.75 0.75 1</ambient>
      <diffuse>0.85 0.85 0.85 1</diffuse>
      <specular>0.9 0.9 0.9 1</specular>
    </material>
  </visual>

  <!-- Collision -->
  <collision name="collision">
    <geometry>
      <mesh>
        <uri>meshes/roller_5_1.stl</uri>
        <scale>0.001 0.001 0.001</scale>
      </mesh>
    </geometry>

    <!-- Same friction model -->
    <surface>
      <friction>
        <ode>
          <mu>0.2</mu>
          <mu2>0.2</mu2>
        </ode>
      </friction>
    </surface>
  </collision>

</link>

<link name="roller_3_1">

  <!-- Keep all rollers consistent with wheel reference frame -->
  <pose>0 0 0.05 0 0 0</pose>

  <!-- Inertial (from URDF) -->
  <inertial>
    <mass>0.014233736590697255</mass>
    <inertia>
      <ixx>2e-06</ixx>
      <iyy>2e-06</iyy>
      <izz>2e-06</izz>
      <ixy>-1e-06</ixy>
      <iyz>-0.0</iyz>
      <ixz>-0.0</ixz>
    </inertia>
  </inertial>

  <!-- Visual -->
  <visual name="visual">
    <geometry>
      <mesh>
        <uri>meshes/roller_3_1.stl</uri>
        <scale>0.001 0.001 0.001</scale>
      </mesh>
    </geometry>

    <!-- Same silver as wheels -->
    <material>
      <ambient>0.75 0.75 0.75 1</ambient>
      <diffuse>0.85 0.85 0.85 1</diffuse>
      <specular>0.9 0.9 0.9 1</specular>
    </material>
  </visual>

  <!-- Collision -->
  <collision name="collision">
    <geometry>
      <mesh>
        <uri>meshes/roller_3_1.stl</uri>
        <scale>0.001 0.001 0.001</scale>
      </mesh>
    </geometry>

    <!-- Same friction model -->
    <surface>
      <friction>
        <ode>
          <mu>0.2</mu>
          <mu2>0.2</mu2>
        </ode>
      </friction>
    </surface>
  </collision>

</link>

<link name="roller_6_1">

  <!-- Keep all rollers consistent with wheel reference frame -->
  <pose>0 0 0.05 0 0 0</pose>

  <!-- Inertial (from URDF) -->
  <inertial>
    <mass>0.014233736590697255</mass>
    <inertia>
      <ixx>2e-06</ixx>
      <iyy>2e-06</iyy>
      <izz>2e-06</izz>
      <ixy>-1e-06</ixy>
      <iyz>-0.0</iyz>
      <ixz>-0.0</ixz>
    </inertia>
  </inertial>

  <!-- Visual -->
  <visual name="visual">
    <geometry>
      <mesh>
        <uri>meshes/roller_6_1.stl</uri>
        <scale>0.001 0.001 0.001</scale>
      </mesh>
    </geometry>

    <!-- Same silver as wheels -->
    <material>
      <ambient>0.75 0.75 0.75 1</ambient>
      <diffuse>0.85 0.85 0.85 1</diffuse>
      <specular>0.9 0.9 0.9 1</specular>
    </material>
  </visual>

  <!-- Collision -->
  <collision name="collision">
    <geometry>
      <mesh>
        <uri>meshes/roller_6_1.stl</uri>
        <scale>0.001 0.001 0.001</scale>
      </mesh>
    </geometry>

    <!-- Same friction model -->
    <surface>
      <friction>
        <ode>
          <mu>0.2</mu>
          <mu2>0.2</mu2>
        </ode>
      </friction>
    </surface>
  </collision>

</link>

<link name="roller_8_1">

  <!-- Keep all rollers consistent with wheel reference frame -->
  <pose>0 0 0.05 0 0 0</pose>

  <!-- Inertial (from URDF) -->
  <inertial>
    <mass>0.014233736590697255</mass>
    <inertia>
      <ixx>2e-06</ixx>
      <iyy>2e-06</iyy>
      <izz>2e-06</izz>
      <ixy>-1e-06</ixy>
      <iyz>-0.0</iyz>
      <ixz>-0.0</ixz>
    </inertia>
  </inertial>

  <!-- Visual -->
  <visual name="visual">
    <geometry>
      <mesh>
        <uri>meshes/roller_8_1.stl</uri>
        <scale>0.001 0.001 0.001</scale>
      </mesh>
    </geometry>

    <!-- Same silver as wheels -->
    <material>
      <ambient>0.75 0.75 0.75 1</ambient>
      <diffuse>0.85 0.85 0.85 1</diffuse>
      <specular>0.9 0.9 0.9 1</specular>
    </material>
  </visual>

  <!-- Collision -->
  <collision name="collision">
    <geometry>
      <mesh>
        <uri>meshes/roller_8_1.stl</uri>
        <scale>0.001 0.001 0.001</scale>
      </mesh>
    </geometry>

    <!-- Same friction model -->
    <surface>
      <friction>
        <ode>
          <mu>0.2</mu>
          <mu2>0.2</mu2>
        </ode>
      </friction>
    </surface>
  </collision>

</link>

<link name="roller_9_1">

  <!-- Keep all rollers consistent with wheel reference frame -->
  <pose>0 0 0.05 0 0 0</pose>

  <!-- Inertial (from URDF) -->
  <inertial>
    <mass>0.014233736590697255</mass>
    <inertia>
      <ixx>2e-06</ixx>
      <iyy>2e-06</iyy>
      <izz>2e-06</izz>
      <ixy>-1e-06</ixy>
      <iyz>-0.0</iyz>
      <ixz>-0.0</ixz>
    </inertia>
  </inertial>

  <!-- Visual -->
  <visual name="visual">
    <geometry>
      <mesh>
        <uri>meshes/roller_9_1.stl</uri>
        <scale>0.001 0.001 0.001</scale>
      </mesh>
    </geometry>

    <!-- Same silver as wheels -->
    <material>
      <ambient>0.75 0.75 0.75 1</ambient>
      <diffuse>0.85 0.85 0.85 1</diffuse>
      <specular>0.9 0.9 0.9 1</specular>
    </material>
  </visual>

  <!-- Collision -->
  <collision name="collision">
    <geometry>
      <mesh>
        <uri>meshes/roller_9_1.stl</uri>
        <scale>0.001 0.001 0.001</scale>
      </mesh>
    </geometry>

    <!-- Same friction model -->
    <surface>
      <friction>
        <ode>
          <mu>0.2</mu>
          <mu2>0.2</mu2>
        </ode>
      </friction>
    </surface>
  </collision>

</link>

<link name="roller_4_1">

  <!-- Keep all rollers consistent with wheel reference frame -->
  <pose>0 0 0.05 0 0 0</pose>

  <!-- Inertial (from URDF) -->
  <inertial>
    <mass>0.014233736590697255</mass>
    <inertia>
      <ixx>2e-06</ixx>
      <iyy>2e-06</iyy>
      <izz>2e-06</izz>
      <ixy>-1e-06</ixy>
      <iyz>-0.0</iyz>
      <ixz>-0.0</ixz>
    </inertia>
  </inertial>

  <!-- Visual -->
  <visual name="visual">
    <geometry>
      <mesh>
        <uri>meshes/roller_4_1.stl</uri>
        <scale>0.001 0.001 0.001</scale>
      </mesh>
    </geometry>

    <!-- Same silver as wheels -->
    <material>
      <ambient>0.75 0.75 0.75 1</ambient>
      <diffuse>0.85 0.85 0.85 1</diffuse>
      <specular>0.9 0.9 0.9 1</specular>
    </material>
  </visual>

  <!-- Collision -->
  <collision name="collision">
    <geometry>
      <mesh>
        <uri>meshes/roller_4_1.stl</uri>
        <scale>0.001 0.001 0.001</scale>
      </mesh>
    </geometry>

    <!-- Same friction model -->
    <surface>
      <friction>
        <ode>
          <mu>0.2</mu>
          <mu2>0.2</mu2>
        </ode>
      </friction>
    </surface>
  </collision>

</link>

<link name="roller_1_1">

  <!-- Keep all rollers consistent with wheel reference frame -->
  <pose>0 0 0.05 0 0 0</pose>

  <!-- Inertial (from URDF) -->
  <inertial>
    <mass>0.014233736590697255</mass>
    <inertia>
      <ixx>2e-06</ixx>
      <iyy>2e-06</iyy>
      <izz>2e-06</izz>
      <ixy>-1e-06</ixy>
      <iyz>-0.0</iyz>
      <ixz>-0.0</ixz>
    </inertia>
  </inertial>

  <!-- Visual -->
  <visual name="visual">
    <geometry>
      <mesh>
        <uri>meshes/roller_1_1.stl</uri>
        <scale>0.001 0.001 0.001</scale>
      </mesh>
    </geometry>

    <!-- Same silver as wheels -->
    <material>
      <ambient>0.75 0.75 0.75 1</ambient>
      <diffuse>0.85 0.85 0.85 1</diffuse>
      <specular>0.9 0.9 0.9 1</specular>
    </material>
  </visual>

  <!-- Collision -->
  <collision name="collision">
    <geometry>
      <mesh>
        <uri>meshes/roller_1_1.stl</uri>
        <scale>0.001 0.001 0.001</scale>
      </mesh>
    </geometry>

    <!-- Same friction model -->
    <surface>
      <friction>
        <ode>
          <mu>0.2</mu>
          <mu2>0.2</mu2>
        </ode>
      </friction>
    </surface>
  </collision>

</link>

<link name="roller_2_1">

  <!-- Keep all rollers consistent with wheel reference frame -->
  <pose>0 0 0.05 0 0 0</pose>

  <!-- Inertial (from URDF) -->
  <inertial>
    <mass>0.014233736590697255</mass>
    <inertia>
      <ixx>2e-06</ixx>
      <iyy>2e-06</iyy>
      <izz>2e-06</izz>
      <ixy>-1e-06</ixy>
      <iyz>-0.0</iyz>
      <ixz>-0.0</ixz>
    </inertia>
  </inertial>

  <!-- Visual -->
  <visual name="visual">
    <geometry>
      <mesh>
        <uri>meshes/roller_2_1.stl</uri>
        <scale>0.001 0.001 0.001</scale>
      </mesh>
    </geometry>

    <!-- Same silver as wheels -->
    <material>
      <ambient>0.75 0.75 0.75 1</ambient>
      <diffuse>0.85 0.85 0.85 1</diffuse>
      <specular>0.9 0.9 0.9 1</specular>
    </material>
  </visual>

  <!-- Collision -->
  <collision name="collision">
    <geometry>
      <mesh>
        <uri>meshes/roller_2_1.stl</uri>
        <scale>0.001 0.001 0.001</scale>
      </mesh>
    </geometry>

    <!-- Same friction model -->
    <surface>
      <friction>
        <ode>
          <mu>0.2</mu>
          <mu2>0.2</mu2>
        </ode>
      </friction>
    </surface>
  </collision>

</link>


    <!-- REAR LEFT -->
 <link name="rear_left_wheel">

  <!-- Same reference height as other wheels -->
  <pose>0 0 0.05 0 0 0</pose>

  <!-- Inertial (unchanged from URDF) -->
  <inertial>
    <mass>0.30282113324994536</mass>
    <inertia>
      <ixx>0.000161</ixx>
      <iyy>0.000183</iyy>
      <izz>0.000161</izz>
      <ixy>-0.0</ixy>
      <iyz>-0.0</iyz>
      <ixz>-0.0</ixz>
    </inertia>
  </inertial>

  <!-- Visual -->
  <visual name="visual">
    <geometry>
      <mesh>
        <uri>meshes/wheel_frame_BL_1.stl</uri>
        <scale>0.001 0.001 0.001</scale>
      </mesh>
    </geometry>
    <material>
      <ambient>0.75 0.75 0.75 1</ambient>
      <diffuse>0.85 0.85 0.85 1</diffuse>
      <specular>0.9 0.9 0.9 1</specular>
    </material>
  </visual>

  <!-- Collision -->
  <collision name="collision">
    <geometry>
      <mesh>
        <uri>meshes/wheel_frame_BL_1.stl</uri>
        <scale>0.001 0.001 0.001</scale>
      </mesh>
    </geometry>

    <!-- Same friction model -->
    <surface>
      <friction>
        <ode>
          <mu>0.2</mu>
          <mu2>0.2</mu2>
        </ode>
      </friction>
    </surface>

  </collision>

</link>

<link name="roller_23_1">

  <!-- Keep all rollers consistent with wheel reference frame -->
  <pose>0 0 0.05 0 0 0</pose>

  <!-- Inertial (from URDF) -->
  <inertial>
    <mass>0.014233736590697255</mass>
    <inertia>
      <ixx>2e-06</ixx>
      <iyy>2e-06</iyy>
      <izz>2e-06</izz>
      <ixy>-1e-06</ixy>
      <iyz>-0.0</iyz>
      <ixz>-0.0</ixz>
    </inertia>
  </inertial>

  <!-- Visual -->
  <visual name="visual">
    <geometry>
      <mesh>
        <uri>meshes/roller_23_1.stl</uri>
        <scale>0.001 0.001 0.001</scale>
      </mesh>
    </geometry>

    <!-- Same silver as wheels -->
    <material>
      <ambient>0.75 0.75 0.75 1</ambient>
      <diffuse>0.85 0.85 0.85 1</diffuse>
      <specular>0.9 0.9 0.9 1</specular>
    </material>
  </visual>

  <!-- Collision -->
  <collision name="collision">
    <geometry>
      <mesh>
        <uri>meshes/roller_23_1.stl</uri>
        <scale>0.001 0.001 0.001</scale>
      </mesh>
    </geometry>

    <!-- Same friction model -->
    <surface>
      <friction>
        <ode>
          <mu>0.2</mu>
          <mu2>0.2</mu2>
        </ode>
      </friction>
    </surface>
  </collision>

</link>

<link name="roller_22_1">

  <!-- Keep all rollers consistent with wheel reference frame -->
  <pose>0 0 0.05 0 0 0</pose>

  <!-- Inertial (from URDF) -->
  <inertial>
    <mass>0.014233736590697255</mass>
    <inertia>
      <ixx>2e-06</ixx>
      <iyy>2e-06</iyy>
      <izz>2e-06</izz>
      <ixy>-1e-06</ixy>
      <iyz>-0.0</iyz>
      <ixz>-0.0</ixz>
    </inertia>
  </inertial>

  <!-- Visual -->
  <visual name="visual">
    <geometry>
      <mesh>
        <uri>meshes/roller_22_1.stl</uri>
        <scale>0.001 0.001 0.001</scale>
      </mesh>
    </geometry>

    <!-- Same silver as wheels -->
    <material>
      <ambient>0.75 0.75 0.75 1</ambient>
      <diffuse>0.85 0.85 0.85 1</diffuse>
      <specular>0.9 0.9 0.9 1</specular>
    </material>
  </visual>

  <!-- Collision -->
  <collision name="collision">
    <geometry>
      <mesh>
        <uri>meshes/roller_22_1.stl</uri>
        <scale>0.001 0.001 0.001</scale>
      </mesh>
    </geometry>

    <!-- Same friction model -->
    <surface>
      <friction>
        <ode>
          <mu>0.2</mu>
          <mu2>0.2</mu2>
        </ode>
      </friction>
    </surface>
  </collision>

</link>

<link name="roller_25_1">

  <!-- Keep all rollers consistent with wheel reference frame -->
  <pose>0 0 0.05 0 0 0</pose>

  <!-- Inertial (from URDF) -->
  <inertial>
    <mass>0.014233736590697255</mass>
    <inertia>
      <ixx>2e-06</ixx>
      <iyy>2e-06</iyy>
      <izz>2e-06</izz>
      <ixy>-1e-06</ixy>
      <iyz>-0.0</iyz>
      <ixz>-0.0</ixz>
    </inertia>
  </inertial>

  <!-- Visual -->
  <visual name="visual">
    <geometry>
      <mesh>
        <uri>meshes/roller_25_1.stl</uri>
        <scale>0.001 0.001 0.001</scale>
      </mesh>
    </geometry>

    <!-- Same silver as wheels -->
    <material>
      <ambient>0.75 0.75 0.75 1</ambient>
      <diffuse>0.85 0.85 0.85 1</diffuse>
      <specular>0.9 0.9 0.9 1</specular>
    </material>
  </visual>

  <!-- Collision -->
  <collision name="collision">
    <geometry>
      <mesh>
        <uri>meshes/roller_25_1.stl</uri>
        <scale>0.001 0.001 0.001</scale>
      </mesh>
    </geometry>

    <!-- Same friction model -->
    <surface>
      <friction>
        <ode>
          <mu>0.2</mu>
          <mu2>0.2</mu2>
        </ode>
      </friction>
    </surface>
  </collision>

</link>

<link name="roller_21_1">

  <!-- Keep all rollers consistent with wheel reference frame -->
  <pose>0 0 0.05 0 0 0</pose>

  <!-- Inertial (from URDF) -->
  <inertial>
    <mass>0.014233736590697255</mass>
    <inertia>
      <ixx>2e-06</ixx>
      <iyy>2e-06</iyy>
      <izz>2e-06</izz>
      <ixy>-1e-06</ixy>
      <iyz>-0.0</iyz>
      <ixz>-0.0</ixz>
    </inertia>
  </inertial>

  <!-- Visual -->
  <visual name="visual">
    <geometry>
      <mesh>
        <uri>meshes/roller_21_1.stl</uri>
        <scale>0.001 0.001 0.001</scale>
      </mesh>
    </geometry>

    <!-- Same silver as wheels -->
    <material>
      <ambient>0.75 0.75 0.75 1</ambient>
      <diffuse>0.85 0.85 0.85 1</diffuse>
      <specular>0.9 0.9 0.9 1</specular>
    </material>
  </visual>

  <!-- Collision -->
  <collision name="collision">
    <geometry>
      <mesh>
        <uri>meshes/roller_21_1.stl</uri>
        <scale>0.001 0.001 0.001</scale>
      </mesh>
    </geometry>

    <!-- Same friction model -->
    <surface>
      <friction>
        <ode>
          <mu>0.2</mu>
          <mu2>0.2</mu2>
        </ode>
      </friction>
    </surface>
  </collision>

</link>

<link name="roller_26_1">

  <!-- Keep all rollers consistent with wheel reference frame -->
  <pose>0 0 0.05 0 0 0</pose>

  <!-- Inertial (from URDF) -->
  <inertial>
    <mass>0.014233736590697255</mass>
    <inertia>
      <ixx>2e-06</ixx>
      <iyy>2e-06</iyy>
      <izz>2e-06</izz>
      <ixy>-1e-06</ixy>
      <iyz>-0.0</iyz>
      <ixz>-0.0</ixz>
    </inertia>
  </inertial>

  <!-- Visual -->
  <visual name="visual">
    <geometry>
      <mesh>
        <uri>meshes/roller_26_1.stl</uri>
        <scale>0.001 0.001 0.001</scale>
      </mesh>
    </geometry>

    <!-- Same silver as wheels -->
    <material>
      <ambient>0.75 0.75 0.75 1</ambient>
      <diffuse>0.85 0.85 0.85 1</diffuse>
      <specular>0.9 0.9 0.9 1</specular>
    </material>
  </visual>

  <!-- Collision -->
  <collision name="collision">
    <geometry>
      <mesh>
        <uri>meshes/roller_26_1.stl</uri>
        <scale>0.001 0.001 0.001</scale>
      </mesh>
    </geometry>

    <!-- Same friction model -->
    <surface>
      <friction>
        <ode>
          <mu>0.2</mu>
          <mu2>0.2</mu2>
        </ode>
      </friction>
    </surface>
  </collision>

</link>

<link name="roller_27_1">

  <!-- Keep all rollers consistent with wheel reference frame -->
  <pose>0 0 0.05 0 0 0</pose>

  <!-- Inertial (from URDF) -->
  <inertial>
    <mass>0.014233736590697255</mass>
    <inertia>
      <ixx>2e-06</ixx>
      <iyy>2e-06</iyy>
      <izz>2e-06</izz>
      <ixy>-1e-06</ixy>
      <iyz>-0.0</iyz>
      <ixz>-0.0</ixz>
    </inertia>
  </inertial>

  <!-- Visual -->
  <visual name="visual">
    <geometry>
      <mesh>
        <uri>meshes/roller_27_1.stl</uri>
        <scale>0.001 0.001 0.001</scale>
      </mesh>
    </geometry>

    <!-- Same silver as wheels -->
    <material>
      <ambient>0.75 0.75 0.75 1</ambient>
      <diffuse>0.85 0.85 0.85 1</diffuse>
      <specular>0.9 0.9 0.9 1</specular>
    </material>
  </visual>

  <!-- Collision -->
  <collision name="collision">
    <geometry>
      <mesh>
        <uri>meshes/roller_27_1.stl</uri>
        <scale>0.001 0.001 0.001</scale>
      </mesh>
    </geometry>

    <!-- Same friction model -->
    <surface>
      <friction>
        <ode>
          <mu>0.2</mu>
          <mu2>0.2</mu2>
        </ode>
      </friction>
    </surface>
  </collision>

</link>

<link name="roller_20_1">

  <!-- Keep all rollers consistent with wheel reference frame -->
  <pose>0 0 0.05 0 0 0</pose>

  <!-- Inertial (from URDF) -->
  <inertial>
    <mass>0.014233736590697255</mass>
    <inertia>
      <ixx>2e-06</ixx>
      <iyy>2e-06</iyy>
      <izz>2e-06</izz>
      <ixy>-1e-06</ixy>
      <iyz>-0.0</iyz>
      <ixz>-0.0</ixz>
    </inertia>
  </inertial>

  <!-- Visual -->
  <visual name="visual">
    <geometry>
      <mesh>
        <uri>meshes/roller_20_1.stl</uri>
        <scale>0.001 0.001 0.001</scale>
      </mesh>
    </geometry>

    <!-- Same silver as wheels -->
    <material>
      <ambient>0.75 0.75 0.75 1</ambient>
      <diffuse>0.85 0.85 0.85 1</diffuse>
      <specular>0.9 0.9 0.9 1</specular>
    </material>
  </visual>

  <!-- Collision -->
  <collision name="collision">
    <geometry>
      <mesh>
        <uri>meshes/roller_20_1.stl</uri>
        <scale>0.001 0.001 0.001</scale>
      </mesh>
    </geometry>

    <!-- Same friction model -->
    <surface>
      <friction>
        <ode>
          <mu>0.2</mu>
          <mu2>0.2</mu2>
        </ode>
      </friction>
    </surface>
  </collision>

</link>

<link name="roller_19_1">

  <!-- Keep all rollers consistent with wheel reference frame -->
  <pose>0 0 0.05 0 0 0</pose>

  <!-- Inertial (from URDF) -->
  <inertial>
    <mass>0.014233736590697255</mass>
    <inertia>
      <ixx>2e-06</ixx>
      <iyy>2e-06</iyy>
      <izz>2e-06</izz>
      <ixy>-1e-06</ixy>
      <iyz>-0.0</iyz>
      <ixz>-0.0</ixz>
    </inertia>
  </inertial>

  <!-- Visual -->
  <visual name="visual">
    <geometry>
      <mesh>
        <uri>meshes/roller_19_1.stl</uri>
        <scale>0.001 0.001 0.001</scale>
      </mesh>
    </geometry>

    <!-- Same silver as wheels -->
    <material>
      <ambient>0.75 0.75 0.75 1</ambient>
      <diffuse>0.85 0.85 0.85 1</diffuse>
      <specular>0.9 0.9 0.9 1</specular>
    </material>
  </visual>

  <!-- Collision -->
  <collision name="collision">
    <geometry>
      <mesh>
        <uri>meshes/roller_19_1.stl</uri>
        <scale>0.001 0.001 0.001</scale>
      </mesh>
    </geometry>

    <!-- Same friction model -->
    <surface>
      <friction>
        <ode>
          <mu>0.2</mu>
          <mu2>0.2</mu2>
        </ode>
      </friction>
    </surface>
  </collision>

</link>

<link name="roller_24_1">

  <!-- Keep all rollers consistent with wheel reference frame -->
  <pose>0 0 0.05 0 0 0</pose>

  <!-- Inertial (from URDF) -->
  <inertial>
    <mass>0.014233736590697255</mass>
    <inertia>
      <ixx>2e-06</ixx>
      <iyy>2e-06</iyy>
      <izz>2e-06</izz>
      <ixy>-1e-06</ixy>
      <iyz>-0.0</iyz>
      <ixz>-0.0</ixz>
    </inertia>
  </inertial>

  <!-- Visual -->
  <visual name="visual">
    <geometry>
      <mesh>
        <uri>meshes/roller_24_1.stl</uri>
        <scale>0.001 0.001 0.001</scale>
      </mesh>
    </geometry>

    <!-- Same silver as wheels -->
    <material>
      <ambient>0.75 0.75 0.75 1</ambient>
      <diffuse>0.85 0.85 0.85 1</diffuse>
      <specular>0.9 0.9 0.9 1</specular>
    </material>
  </visual>

  <!-- Collision -->
  <collision name="collision">
    <geometry>
      <mesh>
        <uri>meshes/roller_24_1.stl</uri>
        <scale>0.001 0.001 0.001</scale>
      </mesh>
    </geometry>

    <!-- Same friction model -->
    <surface>
      <friction>
        <ode>
          <mu>0.2</mu>
          <mu2>0.2</mu2>
        </ode>
      </friction>
    </surface>
  </collision>

</link>


<link name="roller_34_1">

  <!-- Keep all rollers consistent with wheel reference frame -->
  <pose>0 0 0.05 0 0 0</pose>

  <!-- Inertial (from URDF) -->
  <inertial>
    <mass>0.014233736590697255</mass>
    <inertia>
      <ixx>2e-06</ixx>
      <iyy>2e-06</iyy>
      <izz>2e-06</izz>
      <ixy>-1e-06</ixy>
      <iyz>-0.0</iyz>
      <ixz>-0.0</ixz>
    </inertia>
  </inertial>

  <!-- Visual -->
  <visual name="visual">
    <geometry>
      <mesh>
        <uri>meshes/roller_34_1.stl</uri>
        <scale>0.001 0.001 0.001</scale>
      </mesh>
    </geometry>

    <!-- Same silver as wheels -->
    <material>
      <ambient>0.75 0.75 0.75 1</ambient>
      <diffuse>0.85 0.85 0.85 1</diffuse>
      <specular>0.9 0.9 0.9 1</specular>
    </material>
  </visual>

  <!-- Collision -->
  <collision name="collision">
    <geometry>
      <mesh>
        <uri>meshes/roller_34_1.stl</uri>
        <scale>0.001 0.001 0.001</scale>
      </mesh>
    </geometry>

    <!-- Same friction model -->
    <surface>
      <friction>
        <ode>
          <mu>0.2</mu>
          <mu2>0.2</mu2>
        </ode>
      </friction>
    </surface>
  </collision>

</link>

    <!-- REAR RIGHT -->
<link name="rear_right_wheel">

  <!-- Same reference height as the other wheels -->
  <pose>0 0 0.05 0 0 0</pose>

  <!-- Inertial (from URDF, unchanged) -->
  <inertial>
    <mass>0.30282113324994864</mass>
    <inertia>
      <ixx>0.00016</ixx>
      <iyy>0.000183</iyy>
      <izz>0.00016</izz>
      <ixy>0.0</ixy>
      <iyz>0.0</iyz>
      <ixz>-0.0</ixz>
    </inertia>
  </inertial>
  <!-- Visual -->
  <visual name="visual">
    <geometry>
      <mesh>
        <uri>meshes/wheel_frame_BR_1.stl</uri>
        <scale>0.001 0.001 0.001</scale>
      </mesh>
    </geometry>
    <material>
      <ambient>0.75 0.75 0.75 1</ambient>
      <diffuse>0.85 0.85 0.85 1</diffuse>
      <specular>0.9 0.9 0.9 1</specular>
    </material>
  </visual>

  <!-- Collision -->
  <collision name="collision">
    <geometry>
      <mesh>
        <uri>meshes/wheel_frame_BR_1.stl</uri>
        <scale>0.001 0.001 0.001</scale>
      </mesh>
    </geometry>

    <!-- Same friction model -->
    <surface>
      <friction>
        <ode>
          <mu>0.2</mu>
          <mu2>0.2</mu2>
        </ode>
      </friction>
    </surface>

  </collision>

</link>

<link name="roller_30_1">

  <!-- Keep all rollers consistent with wheel reference frame -->
  <pose>0 0 0.05 0 0 0</pose>

  <!-- Inertial (from URDF) -->
  <inertial>
    <mass>0.014233736590697255</mass>
    <inertia>
      <ixx>2e-06</ixx>
      <iyy>2e-06</iyy>
      <izz>2e-06</izz>
      <ixy>-1e-06</ixy>
      <iyz>-0.0</iyz>
      <ixz>-0.0</ixz>
    </inertia>
  </inertial>

  <!-- Visual -->
  <visual name="visual">
    <geometry>
      <mesh>
        <uri>meshes/roller_30_1.stl</uri>
        <scale>0.001 0.001 0.001</scale>
      </mesh>
    </geometry>

    <!-- Same silver as wheels -->
    <material>
      <ambient>0.75 0.75 0.75 1</ambient>
      <diffuse>0.85 0.85 0.85 1</diffuse>
      <specular>0.9 0.9 0.9 1</specular>
    </material>
  </visual>

  <!-- Collision -->
  <collision name="collision">
    <geometry>
      <mesh>
        <uri>meshes/roller_30_1.stl</uri>
        <scale>0.001 0.001 0.001</scale>
      </mesh>
    </geometry>

    <!-- Same friction model -->
    <surface>
      <friction>
        <ode>
          <mu>0.2</mu>
          <mu2>0.2</mu2>
        </ode>
      </friction>
    </surface>
  </collision>

</link>

<link name="roller_32_1">

  <!-- Keep all rollers consistent with wheel reference frame -->
  <pose>0 0 0.05 0 0 0</pose>

  <!-- Inertial (from URDF) -->
  <inertial>
    <mass>0.014233736590697255</mass>
    <inertia>
      <ixx>2e-06</ixx>
      <iyy>2e-06</iyy>
      <izz>2e-06</izz>
      <ixy>-1e-06</ixy>
      <iyz>-0.0</iyz>
      <ixz>-0.0</ixz>
    </inertia>
  </inertial>

  <!-- Visual -->
  <visual name="visual">
    <geometry>
      <mesh>
        <uri>meshes/roller_32_1.stl</uri>
        <scale>0.001 0.001 0.001</scale>
      </mesh>
    </geometry>

    <!-- Same silver as wheels -->
    <material>
      <ambient>0.75 0.75 0.75 1</ambient>
      <diffuse>0.85 0.85 0.85 1</diffuse>
      <specular>0.9 0.9 0.9 1</specular>
    </material>
  </visual>

  <!-- Collision -->
  <collision name="collision">
    <geometry>
      <mesh>
        <uri>meshes/roller_32_1.stl</uri>
        <scale>0.001 0.001 0.001</scale>
      </mesh>
    </geometry>

    <!-- Same friction model -->
    <surface>
      <friction>
        <ode>
          <mu>0.2</mu>
          <mu2>0.2</mu2>
        </ode>
      </friction>
    </surface>
  </collision>

</link>

<link name="roller_31_1">

  <!-- Keep all rollers consistent with wheel reference frame -->
  <pose>0 0 0.05 0 0 0</pose>

  <!-- Inertial (from URDF) -->
  <inertial>
    <mass>0.014233736590697255</mass>
    <inertia>
      <ixx>2e-06</ixx>
      <iyy>2e-06</iyy>
      <izz>2e-06</izz>
      <ixy>-1e-06</ixy>
      <iyz>-0.0</iyz>
      <ixz>-0.0</ixz>
    </inertia>
  </inertial>

  <!-- Visual -->
  <visual name="visual">
    <geometry>
      <mesh>
        <uri>meshes/roller_31_1.stl</uri>
        <scale>0.001 0.001 0.001</scale>
      </mesh>
    </geometry>

    <!-- Same silver as wheels -->
    <material>
      <ambient>0.75 0.75 0.75 1</ambient>
      <diffuse>0.85 0.85 0.85 1</diffuse>
      <specular>0.9 0.9 0.9 1</specular>
    </material>
  </visual>

  <!-- Collision -->
  <collision name="collision">
    <geometry>
      <mesh>
        <uri>meshes/roller_31_1.stl</uri>
        <scale>0.001 0.001 0.001</scale>
      </mesh>
    </geometry>

    <!-- Same friction model -->
    <surface>
      <friction>
        <ode>
          <mu>0.2</mu>
          <mu2>0.2</mu2>
        </ode>
      </friction>
    </surface>
  </collision>

</link>

<link name="roller_29_1">

  <!-- Keep all rollers consistent with wheel reference frame -->
  <pose>0 0 0.05 0 0 0</pose>

  <!-- Inertial (from URDF) -->
  <inertial>
    <mass>0.014233736590697255</mass>
    <inertia>
      <ixx>2e-06</ixx>
      <iyy>2e-06</iyy>
      <izz>2e-06</izz>
      <ixy>-1e-06</ixy>
      <iyz>-0.0</iyz>
      <ixz>-0.0</ixz>
    </inertia>
  </inertial>

  <!-- Visual -->
  <visual name="visual">
    <geometry>
      <mesh>
        <uri>meshes/roller_29_1.stl</uri>
        <scale>0.001 0.001 0.001</scale>
      </mesh>
    </geometry>

    <!-- Same silver as wheels -->
    <material>
      <ambient>0.75 0.75 0.75 1</ambient>
      <diffuse>0.85 0.85 0.85 1</diffuse>
      <specular>0.9 0.9 0.9 1</specular>
    </material>
  </visual>

  <!-- Collision -->
  <collision name="collision">
    <geometry>
      <mesh>
        <uri>meshes/roller_29_1.stl</uri>
        <scale>0.001 0.001 0.001</scale>
      </mesh>
    </geometry>

    <!-- Same friction model -->
    <surface>
      <friction>
        <ode>
          <mu>0.2</mu>
          <mu2>0.2</mu2>
        </ode>
      </friction>
    </surface>
  </collision>

</link>

<link name="roller_28_1">

  <!-- Keep all rollers consistent with wheel reference frame -->
  <pose>0 0 0.05 0 0 0</pose>

  <!-- Inertial (from URDF) -->
  <inertial>
    <mass>0.014233736590697255</mass>
    <inertia>
      <ixx>2e-06</ixx>
      <iyy>2e-06</iyy>
      <izz>2e-06</izz>
      <ixy>-1e-06</ixy>
      <iyz>-0.0</iyz>
      <ixz>-0.0</ixz>
    </inertia>
  </inertial>

  <!-- Visual -->
  <visual name="visual">
    <geometry>
      <mesh>
        <uri>meshes/roller_28_1.stl</uri>
        <scale>0.001 0.001 0.001</scale>
      </mesh>
    </geometry>

    <!-- Same silver as wheels -->
    <material>
      <ambient>0.75 0.75 0.75 1</ambient>
      <diffuse>0.85 0.85 0.85 1</diffuse>
      <specular>0.9 0.9 0.9 1</specular>
    </material>
  </visual>

  <!-- Collision -->
  <collision name="collision">
    <geometry>
      <mesh>
        <uri>meshes/roller_28_1.stl</uri>
        <scale>0.001 0.001 0.001</scale>
      </mesh>
    </geometry>

    <!-- Same friction model -->
    <surface>
      <friction>
        <ode>
          <mu>0.2</mu>
          <mu2>0.2</mu2>
        </ode>
      </friction>
    </surface>
  </collision>

</link>

<link name="roller_35_1">

  <!-- Keep all rollers consistent with wheel reference frame -->
  <pose>0 0 0.05 0 0 0</pose>

  <!-- Inertial (from URDF) -->
  <inertial>
    <mass>0.014233736590697255</mass>
    <inertia>
      <ixx>2e-06</ixx>
      <iyy>2e-06</iyy>
      <izz>2e-06</izz>
      <ixy>-1e-06</ixy>
      <iyz>-0.0</iyz>
      <ixz>-0.0</ixz>
    </inertia>
  </inertial>

  <!-- Visual -->
  <visual name="visual">
    <geometry>
      <mesh>
        <uri>meshes/roller_35_1.stl</uri>
        <scale>0.001 0.001 0.001</scale>
      </mesh>
    </geometry>

    <!-- Same silver as wheels -->
    <material>
      <ambient>0.75 0.75 0.75 1</ambient>
      <diffuse>0.85 0.85 0.85 1</diffuse>
      <specular>0.9 0.9 0.9 1</specular>
    </material>
  </visual>

  <!-- Collision -->
  <collision name="collision">
    <geometry>
      <mesh>
        <uri>meshes/roller_35_1.stl</uri>
        <scale>0.001 0.001 0.001</scale>
      </mesh>
    </geometry>

    <!-- Same friction model -->
    <surface>
      <friction>
        <ode>
          <mu>0.2</mu>
          <mu2>0.2</mu2>
        </ode>
      </friction>
    </surface>
  </collision>

</link>

<link name="roller_36_1">

  <!-- Keep all rollers consistent with wheel reference frame -->
  <pose>0 0 0.05 0 0 0</pose>

  <!-- Inertial (from URDF) -->
  <inertial>
    <mass>0.014233736590697255</mass>
    <inertia>
      <ixx>2e-06</ixx>
      <iyy>2e-06</iyy>
      <izz>2e-06</izz>
      <ixy>-1e-06</ixy>
      <iyz>-0.0</iyz>
      <ixz>-0.0</ixz>
    </inertia>
  </inertial>

  <!-- Visual -->
  <visual name="visual">
    <geometry>
      <mesh>
        <uri>meshes/roller_36_1.stl</uri>
        <scale>0.001 0.001 0.001</scale>
      </mesh>
    </geometry>

    <!-- Same silver as wheels -->
    <material>
      <ambient>0.75 0.75 0.75 1</ambient>
      <diffuse>0.85 0.85 0.85 1</diffuse>
      <specular>0.9 0.9 0.9 1</specular>
    </material>
  </visual>

  <!-- Collision -->
  <collision name="collision">
    <geometry>
      <mesh>
        <uri>meshes/roller_36_1.stl</uri>
        <scale>0.001 0.001 0.001</scale>
      </mesh>
    </geometry>

    <!-- Same friction model -->
    <surface>
      <friction>
        <ode>
          <mu>0.2</mu>
          <mu2>0.2</mu2>
        </ode>
      </friction>
    </surface>
  </collision>

</link>

<link name="roller_33_1">

  <!-- Keep all rollers consistent with wheel reference frame -->
  <pose>0 0 0.05 0 0 0</pose>

  <!-- Inertial (from URDF) -->
  <inertial>
    <mass>0.014233736590697255</mass>
    <inertia>
      <ixx>2e-06</ixx>
      <iyy>2e-06</iyy>
      <izz>2e-06</izz>
      <ixy>-1e-06</ixy>
      <iyz>-0.0</iyz>
      <ixz>-0.0</ixz>
    </inertia>
  </inertial>

  <!-- Visual -->
  <visual name="visual">
    <geometry>
      <mesh>
        <uri>meshes/roller_33_1.stl</uri>
        <scale>0.001 0.001 0.001</scale>
      </mesh>
    </geometry>

    <!-- Same silver as wheels -->
    <material>
      <ambient>0.75 0.75 0.75 1</ambient>
      <diffuse>0.85 0.85 0.85 1</diffuse>
      <specular>0.9 0.9 0.9 1</specular>
    </material>
  </visual>

  <!-- Collision -->
  <collision name="collision">
    <geometry>
      <mesh>
        <uri>meshes/roller_33_1.stl</uri>
        <scale>0.001 0.001 0.001</scale>
      </mesh>
    </geometry>

    <!-- Same friction model -->
    <surface>
      <friction>
        <ode>
          <mu>0.2</mu>
          <mu2>0.2</mu2>
        </ode>
      </friction>
    </surface>
  </collision>

</link>


    <!-- JOINTS -->

    <joint name="front_left_wheel_joint" type="revolute">
      <parent>chassis</parent>
      <child>front_left_wheel</child>
      <axis>
        <xyz>0 1 0</xyz>
        <limit>
          <lower>-1e16</lower>
          <upper>1e16</upper>
        </limit>
        <dynamics>
          <friction>0.0</friction>
          <damping>0.0</damping>
        </dynamics>
      </axis>
    </joint>

    <joint name="roller_14_joint" type="revolute">
      <parent>front_left_wheel</parent>
      <child>roller_14_1</child>
      <axis>
        <xyz>0.720551 0.693402 0</xyz>
      </axis>
      <limit>
        <lower>-1e16</lower>
        <upper>1e16</upper>
      </limit>
    </joint>

    <joint name="roller_16_joint" type="revolute">
      <parent>front_left_wheel</parent>
      <child>roller_16_1</child>
      <axis>
        <xyz>0.551974 0.693402 -0.463161</xyz>
      </axis>
      <limit>
        <lower>-1e16</lower>
        <upper>1e16</upper>
      </limit>
    </joint>

    <joint name="roller_13_joint" type="revolute">
      <parent>front_left_wheel</parent>
      <child>roller_13_1</child>

      <axis>
        <xyz>-0.125122 -0.693402 0.709604</xyz>
        <limit>
          <lower>-1e16</lower>
          <upper>1e16</upper>
        </limit>
      </axis>
    </joint>

    <joint name="roller_12_joint" type="revolute">
      <parent>front_left_wheel</parent>
      <child>roller_12_1</child>

      <axis>
        <xyz>0.360276 -0.693402 0.624016</xyz>
        <limit>
          <lower>-1e16</lower>
          <upper>1e16</upper>
        </limit>
      </axis>
    </joint>

    <joint name="roller_15_joint" type="revolute">
      <parent>front_left_wheel</parent>
      <child>roller_15_1</child>

      <axis>
        <xyz>0.677097 -0.693402 0.246443</xyz>
        <limit>
          <lower>-1e16</lower>
          <upper>1e16</upper>
        </limit>
      </axis>
    </joint>

    <joint name="roller_17_joint" type="revolute">
      <parent>front_left_wheel</parent>
      <child>roller_17_1</child>

      <axis>
        <xyz>0.677097 -0.693402 -0.246443</xyz>
        <limit>
          <lower>-1e16</lower>
          <upper>1e16</upper>
        </limit>
      </axis>
    </joint>

    <joint name="roller_18_joint" type="revolute">
      <parent>front_left_wheel</parent>
      <child>roller_18_1</child>

      <axis>
        <xyz>0.360276 -0.693402 -0.624016</xyz>
        <limit>
          <lower>-1e16</lower>
          <upper>1e16</upper>
        </limit>
      </axis>
    </joint>

    <joint name="roller_10_joint" type="revolute">
      <parent>front_left_wheel</parent>
      <child>roller_10_1</child>

      <axis>
        <xyz>-0.125122 -0.693402 -0.709604</xyz>
        <limit>
          <lower>-1e16</lower>
          <upper>1e16</upper>
        </limit>
      </axis>
    </joint>

    <joint name="roller_11_joint" type="revolute">
      <parent>front_left_wheel</parent>
      <child>roller_11_1</child>

      <axis>
        <xyz>-0.551974 -0.693402 -0.463161</xyz>
        <limit>
          <lower>-1e16</lower>
          <upper>1e16</upper>
        </limit>
      </axis>
    </joint>

    <joint name="front_right_wheel_joint" type="revolute">
      <parent>chassis</parent>
      <child>front_right_wheel</child>
      <axis>
        <xyz>0 1 0</xyz>
        <limit>
          <lower>-1e16</lower>
          <upper>1e16</upper>
        </limit>
        <dynamics>
          <friction>0.0</friction>
          <damping>0.0</damping>
        </dynamics>
      </axis>
    </joint>

    <joint name="roller_7_joint" type="revolute">
      <parent>front_right_wheel</parent>
      <child>roller_7_1</child>
      <axis>
        <xyz>0.720551 -0.693402 0</xyz>
      </axis>
      <limit>
        <lower>-1e16</lower>
        <upper>1e16</upper>
      </limit>
    </joint>

    <joint name="roller_5_joint" type="revolute">
      <parent>front_right_wheel</parent>
      <child>roller_5_1</child>
      <axis>
        <xyz>0.551974 -0.693402 -0.463161</xyz>
      </axis>
      <limit>
        <lower>-1e16</lower>
        <upper>1e16</upper>
      </limit>
    </joint>

    <joint name="roller_3_joint" type="revolute">
      <parent>front_right_wheel</parent>
      <child>roller_3_1</child>

      <axis>
        <xyz>0.125122 -0.693402 -0.709604</xyz>
        <limit>
          <lower>-1e16</lower>
          <upper>1e16</upper>
        </limit>
      </axis>
    </joint>

    <joint name="roller_6_joint" type="revolute">
      <parent>front_right_wheel</parent>
      <child>roller_6_1</child>

      <axis>
        <xyz>-0.360276 -0.693402 -0.624016</xyz>
        <limit>
          <lower>-1e16</lower>
          <upper>1e16</upper>
        </limit>
      </axis>
    </joint>

    <joint name="roller_8_joint" type="revolute">
      <parent>front_right_wheel</parent>
      <child>roller_8_1</child>

      <axis>
        <xyz>-0.677097 -0.693402 -0.246443</xyz>
        <limit>
          <lower>-1e16</lower>
          <upper>1e16</upper>
        </limit>
      </axis>
    </joint>

    <joint name="roller_9_joint" type="revolute">
      <parent>front_right_wheel</parent>
      <child>roller_9_1</child>

      <axis>
        <xyz>-0.677097 -0.693402 0.246443</xyz>
        <limit>
          <lower>-1e16</lower>
          <upper>1e16</upper>
        </limit>
      </axis>
    </joint>

    <joint name="roller_4_joint" type="revolute">
      <parent>front_right_wheel</parent>
      <child>roller_4_1</child>

      <axis>
        <xyz>-0.360276 -0.693402 0.624016</xyz>
        <limit>
          <lower>-1e16</lower>
          <upper>1e16</upper>
        </limit>
      </axis>
    </joint>

    <joint name="roller_1_joint" type="revolute">
      <parent>front_right_wheel</parent>
      <child>roller_1_1</child>

      <axis>
        <xyz>0.125122 -0.693402 0.709604</xyz>
        <limit>
          <lower>-1e16</lower>
          <upper>1e16</upper>
        </limit>
      </axis>
    </joint>

    <joint name="roller_2_joint" type="revolute">
      <parent>front_right_wheel</parent>
      <child>roller_2_1</child>

      <axis>
        <xyz>0.551974 -0.693402 0.463161</xyz>
        <limit>
          <lower>-1e16</lower>
          <upper>1e16</upper>
        </limit>
      </axis>
    </joint>

    <joint name="rear_left_wheel_joint" type="revolute">
      <parent>chassis</parent>
      <child>rear_left_wheel</child>
      <axis>
        <xyz>0 1 0</xyz>
        <limit>
          <lower>-1e16</lower>
          <upper>1e16</upper>
        </limit>
        <dynamics>
          <friction>0.0</friction>
          <damping>0.0</damping>
        </dynamics>
      </axis>
    </joint>

    <joint name="roller_23_joint" type="revolute">
      <parent>rear_left_wheel</parent>
      <child>roller_23_1</child>

      <axis>
        <xyz>0.720551 -0.693402 0</xyz>
        <limit>
          <lower>-1e16</lower>
          <upper>1e16</upper>
        </limit>
      </axis>
    </joint>

    <joint name="roller_22_joint" type="revolute">
      <parent>rear_left_wheel</parent>
      <child>roller_22_1</child>

      <axis>
        <xyz>0.551974 -0.693402 -0.463161</xyz>
        <limit>
          <lower>-1e16</lower>
          <upper>1e16</upper>
        </limit>
      </axis>
    </joint>

    <joint name="roller_25_joint" type="revolute">
      <parent>rear_left_wheel</parent>
      <child>roller_25_1</child>

      <axis>
        <xyz>0.125122 -0.693402 -0.709604</xyz>
        <limit>
          <lower>-1e16</lower>
          <upper>1e16</upper>
        </limit>
      </axis>
    </joint>

    <joint name="roller_21_joint" type="revolute">
      <parent>rear_left_wheel</parent>
      <child>roller_21_1</child>

      <axis>
        <xyz>-0.360276 -0.693402 -0.624016</xyz>
        <limit>
          <lower>-1e16</lower>
          <upper>1e16</upper>
        </limit>
      </axis>
    </joint>

    <joint name="roller_26_joint" type="revolute">
      <parent>rear_left_wheel</parent>
      <child>roller_26_1</child>

      <axis>
        <xyz>-0.677097 -0.693402 -0.246443</xyz>
        <limit>
          <lower>-1e16</lower>
          <upper>1e16</upper>
        </limit>
      </axis>
    </joint>

    <joint name="roller_27_joint" type="revolute">
      <parent>rear_left_wheel</parent>
      <child>roller_27_1</child>

      <axis>
        <xyz>-0.677097 -0.693402 0.246443</xyz>
        <limit>
          <lower>-1e16</lower>
          <upper>1e16</upper>
        </limit>
      </axis>
    </joint>

    <joint name="roller_20_joint" type="revolute">
      <parent>rear_left_wheel</parent>
      <child>roller_20_1</child>

      <axis>
        <xyz>-0.360276 -0.693402 0.624016</xyz>
        <limit>
          <lower>-1e16</lower>
          <upper>1e16</upper>
        </limit>
      </axis>
    </joint>

    <joint name="roller_19_joint" type="revolute">
      <parent>rear_left_wheel</parent>
      <child>roller_19_1</child>

      <axis>
        <xyz>0.125122 -0.693402 0.709604</xyz>
        <limit>
          <lower>-1e16</lower>
          <upper>1e16</upper>
        </limit>
      </axis>
    </joint>

    <joint name="roller_24_joint" type="revolute">
      <parent>rear_left_wheel</parent>
      <child>roller_24_1</child>

      <axis>
        <xyz>0.551974 -0.693402 0.463161</xyz>
        <limit>
          <lower>-1e16</lower>
          <upper>1e16</upper>
        </limit>
      </axis>
    </joint>


    <joint name="rear_right_wheel_joint" type="revolute">
      <parent>chassis</parent>
      <child>rear_right_wheel</child>
      <axis>
        <xyz>0 1 0</xyz>
        <limit>
          <lower>-1e16</lower>
          <upper>1e16</upper>
        </limit>
        <dynamics>
          <friction>0.0</friction>
          <damping>0.0</damping>
        </dynamics>
      </axis>
    </joint>

    <joint name="roller_34_joint" type="revolute">
      <parent>rear_right_wheel</parent>
      <child>roller_34_1</child>

      <axis>
        <xyz>0.720551 0.693402 0</xyz>
        <limit>
          <lower>-1e16</lower>
          <upper>1e16</upper>
        </limit>
      </axis>
    </joint>

    <joint name="roller_30_joint" type="revolute">
      <parent>rear_right_wheel</parent>
      <child>roller_30_1</child>

      <axis>
        <xyz>0.551974 0.693402 -0.463161</xyz>
        <limit>
          <lower>-1e16</lower>
          <upper>1e16</upper>
        </limit>
      </axis>
    </joint>

    <joint name="roller_32_joint" type="revolute">
      <parent>rear_right_wheel</parent>
      <child>roller_32_1</child>

      <axis>
        <xyz>0.125122 0.693402 -0.709604</xyz>
        <limit>
          <lower>-1e16</lower>
          <upper>1e16</upper>
        </limit>
      </axis>
    </joint>

    <joint name="roller_31_joint" type="revolute">
      <parent>rear_right_wheel</parent>
      <child>roller_31_1</child>

      <axis>
        <xyz>-0.360276 0.693402 -0.624016</xyz>
        <limit>
          <lower>-1e16</lower>
          <upper>1e16</upper>
        </limit>
      </axis>
    </joint>

    <joint name="roller_29_joint" type="revolute">
      <parent>rear_right_wheel</parent>
      <child>roller_29_1</child>

      <axis>
        <xyz>-0.677097 0.693402 -0.246443</xyz>
        <limit>
          <lower>-1e16</lower>
          <upper>1e16</upper>
        </limit>
      </axis>
    </joint>

    <joint name="roller_28_joint" type="revolute">
      <parent>rear_right_wheel</parent>
      <child>roller_28_1</child>

      <axis>
        <xyz>0.551974 0.693402 0.463161</xyz>
        <limit>
          <lower>-1e16</lower>
          <upper>1e16</upper>
        </limit>
      </axis>
    </joint>

    <joint name="roller_35_joint" type="revolute">
      <parent>rear_right_wheel</parent>
      <child>roller_35_1</child>

      <axis>
        <xyz>-0.677097 0.693402 0.246443</xyz>
        <limit>
          <lower>-1e16</lower>
          <upper>1e16</upper>
        </limit>
      </axis>
    </joint>

    <joint name="roller_36_joint" type="revolute">
      <parent>rear_right_wheel</parent>
      <child>roller_36_1</child>

      <axis>
        <xyz>-0.360276 0.693402 0.624016</xyz>
        <limit>
          <lower>-1e16</lower>
          <upper>1e16</upper>
        </limit>
      </axis>
    </joint>

    <joint name="roller_33_joint" type="revolute">
      <parent>rear_right_wheel</parent>
      <child>roller_33_1</child>

      <axis>
        <xyz>-0.036391 0.040414 0.023967</xyz>
        <limit>
          <lower>-1e16</lower>
          <upper>1e16</upper>
        </limit>
      </axis>
    </joint>

    <!-- JOINT VELOCITY CONTROLLERS -->

    <plugin
      filename="libignition-gazebo-mecanum-drive-system.so"
      name="ignition::gazebo::systems::MecanumDrive">
      <front_right_joint>front_right_wheel_joint</front_right_joint>
      <front_left_joint>front_left_wheel_joint</front_left_joint>
      <back_left_joint>rear_left_wheel_joint</back_left_joint>
      <back_right_joint>rear_right_wheel_joint</back_right_joint>

      <wheelbase>0.207</wheelbase> <!-- dist wheel front to back -->
      <wheel_separation>0.153</wheel_separation>  <!-- dist wheel left to right -->
      <wheel_radius>0.04</wheel_radius>

      <odom_publish_frequency>50</odom_publish_frequency>
      <publish_odom>true</publish_odom>
      <odom_topic>/odometry</odom_topic>
      <tf_topic>/tf</tf_topic>
      <frame_id>odom</frame_id>
      <child_frame_id>chassis</child_frame_id>

      <topic>/model/simple_robot/cmd_vel</topic>
    </plugin>


  </model>
</sdf>
